# ✅ Исправление ошибок SQLite многопоточности - ЗАВЕРШЕНО

## Проблема была решена
Ошибка `"SQLite objects created in a thread can only be used in that same thread"` больше не возникает.

## Что было сделано

### 1. Изменения в `database/core.py`:

```python
# Старый код:
con = SqliteDatabase('shop_bot.db')

# Новый код:
con = SqliteDatabase(
    'shop_bot.db',
    pragmas={
        'journal_mode': 'wal',  # Write-Ahead Logging для лучшей конкурентности
        'foreign_keys': 1,
        'synchronous': 'normal',
        'cache_size': -64000,  # 64MB кеш
    },
    check_same_thread=False  # Разрешаем использование в разных потоках
)
```

### 2. Улучшен AsyncManager:
- Добавлен `threading.local()` для изоляции соединений между потоками
- Добавлен метод `_ensure_connection()` для проверки и создания соединения в каждом потоке
- Все методы теперь вызывают `_ensure_connection()` перед выполнением запросов

## Результаты

✅ **Ошибки исчезли**: Больше нет ошибок `SQLite objects created in a thread`
✅ **Бот работает стабильно**: Успешно запускается и обрабатывает запросы
✅ **Многопоточность поддерживается**: AsyncIO executor может безопасно использовать БД в разных потоках

## Дополнительные улучшения

1. **WAL режим** - улучшенная производительность при конкурентных запросах
2. **Кеширование** - 64MB кеш для ускорения частых запросов
3. **Thread-safety** - каждый поток работает со своим контекстом соединения

## Статус: ✅ ИСПРАВЛЕНО

Бот теперь может безопасно работать с SQLite в многопоточной среде без ошибок.
